Workbook

Sheet RAINFALL
A2: YEAR | B2: WEEK | C2: MONDAY | D2: TUESDAY | E2: WEDNESDAY | F2: THURSDAY | G2: FRIDAY | H2: SATURDAY | I2: Weekly Rain Fall
A3: 2023 | B3: 1 | C3: 0 | D3: 0 | E3: 0 | F3: 0 | G3: 0 | H3: 0 | I3: 0
B4: 2 | C4: 0 | D4: 0 | E4: 0 | F4: 0 | G4: 0 | H4: 0 | I4: 0
B5: 3 | C5: 0 | D5: 11 | E5: 2 | F5: 0 | G5: 0 | H5: 0 | I5: 13
B6: 4 | C6: 0 | D6: 0 | E6: 0 | F6: 0 | G6: 0 | H6: 0 | I6: 0
B7: 5 | C7: 0 | D7: 3 | E7: 9 | F7: 6 | G7: 0 | H7: 0 | I7: 18
B8: 6 | C8: 0 | D8: 0 | E8: 0 | F8: 0 | G8: 0 | H8: 0 | I8: 0
B9: 7 | C9: 0 | D9: 0 | E9: 0 | F9: 0 | G9: 0 | H9: 0 | I9: 0
B10: 8 | C10: 0 | D10: 0 | E10: 0 | F10: 0 | G10: 0 | H10: 0 | I10: 0
B11: 9 | C11: 0 | D11: 0 | E11: 0 | F11: 0 | G11: 0 | H11: 0 | I11: 0
B12: 10 | C12: 0 | D12: 13 | E12: 0 | F12: 0 | G12: 0 | H12: 0 | I12: 13
B13: 11 | C13: 0 | D13: 0 | E13: 4 | F13: 1 | G13: 63 | H13: 0 | I13: 68
B14: 12 | C14: 93 | D14: 0 | E14: 0 | F14: 0 | G14: 14 | H14: 22 | I14: 129
B15: 13 | C15: 2 | D15: 0 | E15: 0 | F15: 0 | G15: 34 | H15: 9 | I15: 45
... B54: 52 | C54: 0 | D54: 0 | E54: 2 | F54: 0 | G54: 0 | H54: 0 | I54: 2
A55: 2024 | B55: 1 | C55: 0 | D55: 68 | E55: 0 | F55: 0 | G55: 0 | H55: 0 | I55: 68
B56: 2 | C56: 6 | D56: 25 | E56: 0 | F56: 0.5 | G56: 0 | H56: 0 | I56: 31.5
B57: 3 | C57: 0 | D57: 0 | E57: 0 | F57: 0 | G57: 0 | H57: 0 | I57: 0
B58: 4 | C58: 0 | D58: 0 | E58: 0 | F58: 0 | G58: 0 | H58: 0 | I58: 0
B59: 5 | C59: 0 | D59: 0 | E59: 14 | F59: 3.5 | G59: 0 | H59: 0 | I59: 17.5
B60: 6 | C60: 0 | D60: 0 | E60: 0 | F60: 0 | G60: 0 | H60: 0 | I60: 0
B61: 7 | C61: 0 | D61: 0 | E61: 0 | F61: 0 | G61: 0 | H61: 0 | I61: 0
B62: 8 | C62: 0 | D62: 0 | E62: 0 | F62: 0 | G62: 0 | H62: 7 | I62: 7
B63: 9 | C63: 0 | D63: 0 | E63: 0 | F63: 0 | G63: 0 | H63: 0 | I63: 0
B64: 10 | C64: 0 | D64: 0 | E64: 0 | F64: 0 | G64: 0 | H64: 0 | I64: 0
B65: 11 | C65: 0 | D65: 0 | E65: 0 | F65: 0 | G65: 0 | H65: 0 | I65: 0
B66: 12 | C66: 0 | D66: 0 | E66: 0 | F66: 0 | G66: 0 | H66: 11 | I66: 11
B67: 13 | C67: 0 | D67: 0 | E67: 0 | F67: 0 | G67: 0 | H67: 0 | I67: 0
... B106: 52 | C106: 23 | D106: 0 | E106: 0 | F106: 0 | G106: 0 | H106: 0 | I106: 23
A107: 2025 | B107: 1 | D107: 20 | E107: 1 | F107: 33 | G107: 0 | H107: 0 | I107: 54
B108: 2 | C108: 0 | D108: 0 | E108: 0 | F108: 0 | G108: 0 | H108: 0 | I108: 0
B109: 3 | C109: 0 | D109: 0 | E109: 54 | F109: 0 | G109: 20 | H109: 0 | I109: 74
B110: 4 | C110: 49 | D110: 1 | E110: 2.5 | F110: 0 | G110: 0 | H110: 38 | I110: 90.5
B111: 5 | C111: 0 | D111: 0 | E111: 0 | F111: 18 | G111: 0 | H111: 9 | I111: 27
B112: 6 | C112: 0 | D112: 0 | E112: 0 | F112: 0 | G112: 0 | H112: 0 | I112: 0
B113: 7 | C113: 0 | D113: 0 | E113: 0 | F113: 0 | G113: 0 | H113: 0 | I113: 0
B114: 8 | C114: 0 | D114: 0 | E114: 0 | F114: 0 | G114: 0 | H114: 0 | I114: 0
B115: 9 | C115: 0 | D115: 0 | E115: 0 | F115: 0 | G115: 0 | H115: 0 | I115: 0
B116: 10 | C116: 57 | D116: 0 | E116: 0 | F116: 0 | G116: 0 | H116: 15 | I116: 72
B117: 11 | C117: 0 | D117: 0 | E117: 0 | F117: 0 | G117: 0 | H117: 0 | I117: 0
...

Sheet MINIMUM TEM
A2: YEAR | B2: WEEK | C2: MONDAY | D2: TUESDAY | E2: WEDNESDAY | F2: THURSDAY | G2: FRIDAY | H2: SATURDAY | I2: Avg Weekly Min Temperature
A3: 2023 | B3: 1 | C3: 31 | D3: 31 | E3: 29 | F3: 30 | H3: 32 | I3: =AVERAGE(C3:H3) -> 30.6
B4: 2 | C4: 30 | D4: 31 | E4: 30 | F4: 32 | G4: 30 | H4: 33 | I4: =AVERAGE(C4:H4) -> 31
B5: 3 | C5: 28 | D5: 24 | E5: 32 | F5: 34 | G5: 26 | H5: 24 | I5: =AVERAGE(C5:H5) -> 28
B6: 4 | C6: 31 | D6: 30 | E6: 34 | F6: 32 | G6: 28 | H6: 28 | I6: =AVERAGE(C6:H6) -> 30.5
B7: 5 | C7: 28 | D7: 26 | E7: 22 | F7: 28 | G7: 22 | I7: =AVERAGE(C7:H7) -> 25.2
B8: 6 | C8: 21 | D8: 26 | E8: 28 | F8: 28 | G8: 30 | H8: 20 | I8: =AVERAGE(C8:H8) -> 25.5
B9: 7 | C9: 20 | D9: 20 | E9: 18 | F9: 18 | G9: 18 | H9: 20 | I9: =AVERAGE(C9:H9) -> 19
B10: 8 | C10: 22 | D10: 21 | E10: 24 | F10: 20 | G10: 21 | I10: =AVERAGE(C10:H10) -> 21.6
B11: 9 | C11: 28 | D11: 21 | E11: 31 | F11: 29 | G11: 28 | I11: =AVERAGE(C11:H11) -> 27.4
B12: 10 | D12: 20 | E12: 18 | F12: 22 | G12: 22 | H12: 22 | I12: =AVERAGE(C12:H12) -> 20.8
B13: 11 | C13: 21 | D13: 21 | E13: 20 | F13: 26 | G13: 21 | H13: 21 | I13: =AVERAGE(C13:H13) -> 21.666667
B14: 12 | C14: 21 | D14: 21 | E14: 21 | F14: 24 | G14: 21 | H14: 22 | I14: =AVERAGE(C14:H14) -> 21.666667
B15: 13 | C15: 22 | D15: 22 | E15: 24 | F15: 22 | G15: 22 | I15: =AVERAGE(C15:H15) -> 22.4
B16: 14 | C16: 20 | D16: 22 | F16: 21 | G16: 24 | H16: 24 | I16: =AVERAGE(C16:H16) -> 22.2
B17: 15 | C17: 22 | D17: 22 | I17: =AVERAGE(C17:H17) -> 22
B18: 16 | C18: 24 | D18: 22 | E18: 22 | F18: 24 | G18: 23 | I18: =AVERAGE(C18:H18) -> 23
B19: 17 | C19: 24 | D19: 24 | E19: 28 | F19: 24 | G19: 34 | H19: 32 | I19: =AVERAGE(C19:H19) -> 27.666667
B20: 18 | C20: 28 | D20: 27 | E20: 28 | F20: 28 | I20: =AVERAGE(C20:H20) -> 27.75
B21: 19 | D21: 28 | E21: 28 | F21: 27 | G21: 26 | H21: 24 | I21: =AVERAGE(C21:H21) -> 26.6
B22: 20 | C22: 24 | D22: 18 | E22: 24 | F22: 24 | G22: 24 | H22: 24 | I22: =AVERAGE(C22:H22) -> 23
B23: 21 | C23: 22 | D23: 23 | E23: 24 | F23: 28 | G23: 32 | H23: 30 | I23: =AVERAGE(C23:H23) -> 26.5
B24: 22 | C24: 28 | D24: 28 | F24: 24 | G24: 26 | I24: =AVERAGE(C24:H24) -> 26.5
B25: 23 | C25: 22 | D25: 26 | E25: 24 | F25: 24 | G25: 26 | H25: 26 | I25: =AVERAGE(C25:H25) -> 24.666667
B26: 24 | C26: 26 | D26: 26 | E26: 26 | F26: 26 | G26: 26 | H26: 25 | I26: =AVERAGE(C26:H26) -> 25.833333
B27: 25 | C27: 26 | D27: 26 | E27: 26 | F27: 26 | G27: 26 | H27: 26 | I27: =AVERAGE(C27:H27) -> 26
B28: 26 | C28: 26 | D28: 27 | E28: 27 | F28: 27 | G28: 27 | I28: =AVERAGE(C28:H28) -> 26.8
B29: 27 | D29: 26 | E29: 26 | F29: 26 | G29: 30 | H29: 30 | I29: =AVERAGE(C29:H29) -> 27.6
B30: 28 | C30: 26 | D30: 27 | E30: 26 | F30: 30 | G30: 30 | H30: 30 | I30: =AVERAGE(C30:H30) -> 28.166667
B31: 29 | C31: 26 | D31: 30 | E31: 30 | F31: 34 | G31: 26 | H31: 27 | I31: =AVERAGE(C31:H31) -> 28.833333
B32: 30 | C32: 27 | D32: 30 | E32: 30 | F32: 26 | G32: 26 | I32: =AVERAGE(C32:H32) -> 27.8
B33: 31 | C33: 26 | E33: 27 | F33: 27 | G33: 28 | H33: 28 | I33: =AVERAGE(C33:H33) -> 27.2
B34: 32 | C34: 30 | D34: 30 | E34: 26 | F34: 26 | G34: 26 | H34: 30 | I34: =AVERAGE(C34:H34) -> 28
B35: 33 | C35: 28 | D35: 27 | E35: 28 | G35: 28 | H35: 27 | I35: =AVERAGE(C35:H35) -> 27.6
B36: 34 | C36: 28 | D36: 28 | E36: 28 | F36: 27 | G36: 30 | H36: 28 | I36: =AVERAGE(C36:H36) -> 28.166667
B37: 35 | C37: 22 | D37: 33 | F37: 29 | G37: 20 | H37: 23 | I37: =AVERAGE(C37:H37) -> 25.4
B38: 36 | C38: 23 | D38: 33 | E38: 22 | F38: 22 | G38: 23 | H38: 20 | I38: =AVERAGE(C38:H38) -> 23.833333
B39: 37 | C39: 22 | D39: 22 | F39: 20 | G39: 20 | H39: 20 | I39: =AVERAGE(C39:H39) -> 20.8
B40: 38 | C40: 35 | D40: 35 | E40: 30 | F40: 30 | G40: 30 | H40: 33 | I40: =AVERAGE(C40:H40) -> 32.166667
B41: 39 | C41: 30 | D41: 28 | E41: 28 | H41: 22 | I41: =AVERAGE(C41:H41) -> 27
...

Sheet MAXIMUM TEM
A2: YEAR | B2: WEEK | C2: MONDAY | D2: TUESDAY | E2: WEDNESDAY | F2: THURSDAY | G2: FRIDAY | H2: SATURDAY | I2: Avg Weekly Max Temperature
A3: 2023 | B3: 1 | C3: 32 | D3: 32 | E3: 30 | F3: 31 | H3: 34 | I3: =AVERAGE(C3:H3) -> 31.8
B4: 2 | C4: 32 | D4: 34 | E4: 31 | F4: 33 | G4: 34 | H4: 34 | I4: =AVERAGE(C4:H4) -> 33
B5: 3 | C5: 32 | D5: 25 | E5: 35 | F5: 35 | G5: 32 | H5: 25 | I5: =AVERAGE(C5:H5) -> 30.666667
B6: 4 | C6: 32 | D6: 31 | E6: 36 | F6: 33 | G6: 29 | H6: 34 | I6: =AVERAGE(C6:H6) -> 32.5
B7: 5 | C7: 32 | D7: 32 | E7: 28 | F7: 30 | G7: 32 | I7: =AVERAGE(C7:H7) -> 30.8
B8: 6 | C8: 32 | D8: 34 | E8: 34 | F8: 36 | G8: 36 | H8: 32 | I8: =AVERAGE(C8:H8) -> 34
B9: 7 | C9: 36 | D9: 36 | E9: 36 | F9: 35 | G9: 35 | H9: 35 | I9: =AVERAGE(C9:H9) -> 35.5
B10: 8 | C10: 35 | D10: 35 | E10: 37 | F10: 36 | G10: 37 | I10: =AVERAGE(C10:H10) -> 36
B11: 9 | C11: 33 | D11: 33 | E11: 32 | F11: 33 | G11: 32 | I11: =AVERAGE(C11:H11) -> 32.6
B12: 10 | D12: 34 | E12: 36 | F12: 33 | G12: 31 | H12: 34 | I12: =AVERAGE(C12:H12) -> 33.6
B13: 11 | C13: 35 | D13: 36 | E13: 35 | F13: 36 | G13: 36 | H13: 36 | I13: =AVERAGE(C13:H13) -> 35.666667
B14: 12 | C14: 35 | D14: 35 | E14: 35 | F14: 35 | G14: 36 | H14: 36 | I14: =AVERAGE(C14:H14) -> 35.333333
B15: 13 | C15: 36 | D15: 36 | E15: 36 | F15: 38 | G15: 36 | I15: =AVERAGE(C15:H15) -> 36.4
B16: 14 | C16: 32 | D16: 36 | F16: 35 | G16: 36 | H16: 35 | I16: =AVERAGE(C16:H16) -> 34.8
B17: 15 | C17: 36 | D17: 37 | I17: =AVERAGE(C17:H17) -> 36.5
B18: 16 | C18: 37 | D18: 37 | E18: 37 | F18: 37 | G18: 36 | I18: =AVERAGE(C18:H18) -> 36.8
B19: 17 | C19: 36 | D19: 36 | E19: 36 | F19: 37 | G19: 36 | H19: 34 | I19: =AVERAGE(C19:H19) -> 35.833333
B20: 18 | C20: 32 | D20: 32 | E20: 32 | F20: 32 | I20: =AVERAGE(C20:H20) -> 32
B21: 19 | D21: 32 | E21: 32 | F21: 32 | G21: 33 | H21: 34 | I21: =AVERAGE(C21:H21) -> 32.6
B22: 20 | C22: 36 | D22: 35 | E22: 31 | F22: 38 | G22: 34 | H22: 35 | I22: =AVERAGE(C22:H22) -> 34.833333
B23: 21 | C23: 31 | D23: 30 | E23: 35 | F23: 34 | G23: 34 | H23: 34 | I23: =AVERAGE(C23:H23) -> 33
B24: 22 | C24: 35 | D24: 34 | F24: 30 | G24: 30 | I24: =AVERAGE(C24:H24) -> 32.25
B25: 23 | C25: 31 | D25: 31 | E25: 30 | F25: 30 | G25: 30 | H25: 30 | I25: =AVERAGE(C25:H25) -> 30.333333
B26: 24 | C26: 31 | D26: 32 | E26: 30 | F26: 34 | G26: 31 | H26: 31 | I26: =AVERAGE(C26:H26) -> 31.5
B27: 25 | C27: 31 | D27: 32 | E27: 34 | F27: 32 | G27: 34 | H27: 34 | I27: =AVERAGE(C27:H27) -> 32.833333
B28: 26 | C28: 31 | D28: 32 | E28: 32 | F28: 32 | G28: 31 | I28: =AVERAGE(C28:H28) -> 31.6
B29: 27 | D29: 32 | E29: 34 | F29: 32 | G29: 32 | H29: 36 | I29: =AVERAGE(C29:H29) -> 33.2
B30: 28 | C30: 31 | D30: 31 | E30: 32 | F30: 36 | G30: 32 | H30: 32 | I30: =AVERAGE(C30:H30) -> 32.333333
B31: 29 | C31: 34 | D31: 36 | E31: 32 | F31: 36 | G31: 34 | H31: 30 | I31: =AVERAGE(C31:H31) -> 33.666667
B32: 30 | C32: 32 | D32: 32 | E32: 36 | F32: 32 | G32: 30 | I32: =AVERAGE(C32:H32) -> 32.4
B33: 31 | C33: 36 | E33: 34 | F33: 36 | G33: 36 | H33: 36 | I33: =AVERAGE(C33:H33) -> 35.6
B34: 32 | C34: 36 | D34: 36 | E34: 35 | F34: 36 | G34: 34 | H34: 36 | I34: =AVERAGE(C34:H34) -> 35.5
B35: 33 | C35: 33 | D35: 34 | E35: 36 | G35: 34 | H35: 36 | I35: =AVERAGE(C35:H35) -> 34.6
B36: 34 | C36: 36 | D36: 36 | E36: 36 | F36: 35 | G36: 33 | H36: 36 | I36: =AVERAGE(C36:H36) -> 35.333333
B37: 35 | C37: 37 | D37: 37 | F37: 34 | G37: 27 | H37: 27 | I37: =AVERAGE(C37:H37) -> 32.4
B38: 36 | C38: 24 | D38: 37 | E38: 30 | F38: 30 | G38: 30 | H38: 28 | I38: =AVERAGE(C38:H38) -> 29.833333
B39: 37 | C39: 34 | D39: 33 | F39: 28 | G39: 28 | H39: 28 | I39: =AVERAGE(C39:H39) -> 30.2
B40: 38 | C40: 38 | D40: 38 | E40: 33 | F40: 33 | G40: 33 | H40: 34 | I40: =AVERAGE(C40:H40) -> 34.833333
B41: 39 | C41: 34 | D41: 30 | E41: 30 | H41: 34 | I41: =AVERAGE(C41:H41) -> 32
...

Sheet Summary
A1: YEAR | B1: WEEK | C1: Avg Weekly Min Temperature | D1: Avg Weekly Max Temperature | E1: Min and Max Temperature Difference | F1: Weekly Rain Fall
A2: 2023 | B2: 1 | C2: ='MINIMUM TEM'!I3 -> 30.6 | D2: ='MAXIMUM TEM'!I3 -> 31.8 | E2: =D2-C2 -> 1.2 | F2: 0
A3: 2023 | B3: 2 | C3: ='MINIMUM TEM'!I4 -> 31 | D3: ='MAXIMUM TEM'!I4 -> 33 | E3: =D3-C3 -> 2 | F3: 0
A4: 2023 | B4: 3 | C4: ='MINIMUM TEM'!I5 -> 28 | D4: ='MAXIMUM TEM'!I5 -> 30.666667 | E4: =D4-C4 -> 2.6666667 | F4: 13
A5: 2023 | B5: 4 | C5: ='MINIMUM TEM'!I6 -> 30.5 | D5: ='MAXIMUM TEM'!I6 -> 32.5 | E5: =D5-C5 -> 2 | F5: 0
A6: 2023 | B6: 5 | C6: ='MINIMUM TEM'!I7 -> 25.2 | D6: ='MAXIMUM TEM'!I7 -> 30.8 | E6: =D6-C6 -> 5.6 | F6: 18
A7: 2023 | B7: 6 | C7: ='MINIMUM TEM'!I8 -> 25.5 | D7: ='MAXIMUM TEM'!I8 -> 34 | E7: =D7-C7 -> 8.5 | F7: 0
A8: 2023 | B8: 7 | C8: ='MINIMUM TEM'!I9 -> 19 | D8: ='MAXIMUM TEM'!I9 -> 35.5 | E8: =D8-C8 -> 16.5 | F8: 0
A9: 2023 | B9: 8 | C9: ='MINIMUM TEM'!I10 -> 21.6 | D9: ='MAXIMUM TEM'!I10 -> 36 | E9: =D9-C9 -> 14.4 | F9: 0
A10: 2023 | B10: 9 | C10: ='MINIMUM TEM'!I11 -> 27.4 | D10: ='MAXIMUM TEM'!I11 -> 32.6 | E10: =D10-C10 -> 5.2 | F10: 0
A11: 2023 | B11: 10 | C11: ='MINIMUM TEM'!I12 -> 20.8 | D11: ='MAXIMUM TEM'!I12 -> 33.6 | E11: =D11-C11 -> 12.8 | F11: 13
A12: 2023 | B12: 11 | C12: ='MINIMUM TEM'!I13 -> 21.666667 | D12: ='MAXIMUM TEM'!I13 -> 35.666667 | E12: =D12-C12 -> 14 | F12: 68
A13: 2023 | B13: 12 | C13: ='MINIMUM TEM'!I14 -> 21.666667 | D13: ='MAXIMUM TEM'!I14 -> 35.333333 | E13: =D13-C13 -> 13.666667 | F13: 129
... A157: 2025 | B157: 52 | C157: ='MINIMUM TEM'!I158 -> 22.8 | D157: ='MAXIMUM TEM'!I158 -> 33 | E157: =D157-C157 -> 10.2 | F157: 0
A158: 2026 | B158: 1 | C158: 23.5 | D158: 30.5 | E158: =D158-C158 -> 7 | F158: 10
A159: 2026 | B159: 2 | C159: 28.6 | D159: 32.4 | E159: =D159-C159 -> 3.8 | F159: 23
A160: 2026 | B160: 3 | C160: 23.333333 | D160: 32.666667 | E160: =D160-C160 -> 9.3333333 | F160: 0
A161: 2026 | B161: 4 | C161: 23 | D161: 32.5 | E161: =D161-C161 -> 9.5 | F161: 0
A162: 2026 | B162: 5 | C162: 24.2 | D162: 32.2 | E162: =D162-C162 -> 8 | F162: 0
A163: 2026 | B163: 6 | C163: 25.333333 | D163: 32.5 | E163: =D163-C163 -> 7.1666667 | F163: 0
A164: 2026 | B164: 7 | C164: 24 | D164: 31.333333 | E164: =D164-C164 -> 7.3333333 | F164: 0
A165: 2026 | B165: 8 | C165: 22.666667 | D165: 33.333333 | E165: =D165-C165 -> 10.666667 | F165: 0
A166: 2026 | B166: 9 | C166: 24.8 | D166: 34.8 | E166: =D166-C166 -> 10 | F166: 0
A167: 2026 | B167: 10 | C167: 22 | D167: 35.5 | E167: =D167-C167 -> 13.5 | F167: 0
A168: 2026 | B168: 11 | C168: 26.833333 | D168: 35.833333 | E168: =D168-C168 -> 9 | F168: 48
A169: 2026 | B169: 12 | C169: 27.833333 | D169: 37.666667 | E169: =D169-C169 -> 9.8333333 | F169: 42
... A196: 2026 | B196: 39 | C196: 23.833333 | D196: 33.166667 | E196: =D196-C196 -> 9.3333333 | F196: 140
A197: 2026 | B197: 40 | F197: 25
A198: 2026 | B198: 41
A199: 2026 | B199: 42
A200: 2026 | B200: 43
A201: 2026 | B201: 44
A202: 2026 | B202: 45
A203: 2026 | B203: 46
A204: 2026 | B204: 47
A205: 2026 | B205: 48
A206: 2026 | B206: 49
A207: 2026 | B207: 50
A208: 2026 | B208: 51
A209: 2026 | B209: 52

Sheet Summary Rain fall
B1: Weekly Rain Fall
A2: Week Number | B2: 2023 | C2: 2024 | D2: 2025 | E2: 2026
A3: 1 | B3: 0 | C3: 68 | D3: 54 | E3: 10
A4: 2 | B4: 0 | C4: 31.5 | D4: 0 | E4: 23
A5: 3 | B5: 13 | C5: 0 | D5: 74 | E5: 0
A6: 4 | B6: 0 | C6: 0 | D6: 90.5 | E6: 0
A7: 5 | B7: 18 | C7: 17.5 | D7: 27 | E7: 0
A8: 6 | B8: 0 | C8: 0 | D8: 0 | E8: 0
A9: 7 | B9: 0 | C9: 0 | D9: 0 | E9: 0
A10: 8 | B10: 0 | C10: 7 | D10: 0 | E10: 0
A11: 9 | B11: 0 | C11: 0 | D11: 0 | E11: 0
A12: 10 | B12: 13 | C12: 0 | D12: 72 | E12: 0
A13: 11 | B13: 68 | C13: 0 | D13: 0 | E13: 48
A14: 12 | B14: 129 | C14: 11 | D14: 36.5 | E14: 42
... A26: 24 | B26: 78 | C26: 38 | D26: 56 | E26: 58
A27: 25 | B27: 0 | C27: 38 | D27: 75
A28: 26 | B28: 0 | C28: 35 | D28: 34
A29: 27 | B29: 64.5 | C29: 22.5 | D29: 0
A30: 28 | B30: 6 | C30: 56.5 | D30: 0
A31: 29 | B31: 0 | C31: 14 | D31: 0
A32: 30 | B32: 0 | C32: 14 | D32: 58
A33: 31 | B33: 0 | C33: 50 | D33: 0
A34: 32 | B34: 0 | C34: 0 | D34: 43
A35: 33 | B35: 0 | C35: 31 | D35: 13
A36: 34 | B36: 0 | C36: 61 | D36: 0
A37: 35 | B37: 62 | C37: 8.5 | D37: 3
A38: 36 | B38: 126 | C38: 57.5 | D38: 0
... A54: 52 | B54: 2 | C54: 23 | D54: 0
A56: Month | B56: 2023 | C56: 2024 | D56: 2025 | E56: 2026
A57: January | B57: =SUM(B3:B7) -> 31 | C57: =SUM(C3:C7) -> 117 | D57: =SUM(D3:D7) -> 245.5 | E57: =SUM(E3:E7) -> 33
A58: February | B58: =SUM(B8:B11) -> 0 | C58: =SUM(C8:C11) -> 7 | D58: =SUM(D8:D11) -> 0 | E58: =SUM(E8:E11) -> 0
A59: March | B59: =SUM(B12:B16) -> 258 | C59: =SUM(C12:C16) -> 18 | D59: =SUM(D12:D16) -> 163 | E59: =SUM(E12:E16) -> 106
A60: April | B60: =SUM(B17:B21) -> 314 | C60: =SUM(C17:C21) -> 244.5 | D60: =SUM(D17:D21) -> 191 | E60: =SUM(E17:E21) -> 283
A61: May
A62: June
A63: July
A64: August
A65: September
A66: October
A67: November
...

Sheet Summary Min tem
B1: Avg Weekly Min Temperature
A2: Week Number | B2: 2023 | C2: 2024 | D2: 2025
A3: 1 | B3: 30.6 | C3: 22.5 | D3: 24.833333
A4: 2 | B4: 31 | C4: 22.833333 | D4: 27.333333
A5: 3 | B5: 28 | C5: 20.8 | D5: 26.5
A6: 4 | B6: 30.5 | C6: 21.8 | D6: 26.166667
A7: 5 | B7: 25.2 | C7: 22 | D7: 26.333333
A8: 6 | B8: 25.5 | C8: 22 | D8: 21.8
A9: 7 | B9: 19 | C9: 20.833333 | D9: 22.333333
A10: 8 | B10: 21.6 | C10: 22.6 | D10: 20.666667
A11: 9 | B11: 27.4 | C11: 21.833333 | D11: 23.833333
A12: 10 | B12: 20.8 | C12: 20.5 | D12: 21.833333
A13: 11 | B13: 21.666667 | C13: 27.166667 | D13: 26.333333
A14: 12 | B14: 21.666667 | C14: 23.333333 | D14: 25.5
... A54: 52 | B54: 20.75 | C54: 24.8 | D54: 21

Sheet Summary Max tem
B1: Avg Weekly Max Temperature
A2: Week Number | B2: 2023 | C2: 2024 | D2: 2025
A3: 1 | B3: 31.8 | C3: 33.666667 | D3: 32
A4: 2 | B4: 33 | C4: 33 | D4: 32.833333
A5: 3 | B5: 30.666667 | C5: 34.4 | D5: 32.25
A6: 4 | B6: 32.5 | C6: 34.4 | D6: 31.5
A7: 5 | B7: 30.8 | C7: 35.333333 | D7: 32.833333
A8: 6 | B8: 34 | C8: 35.333333 | D8: 34.2
A9: 7 | B9: 35.5 | C9: 35 | D9: 34
A10: 8 | B10: 36 | C10: 36.4 | D10: 34.833333
A11: 9 | B11: 32.6 | C11: 35.833333 | D11: 35.333333
A12: 10 | B12: 33.6 | C12: 36.333333 | D12: 35.333333
A13: 11 | B13: 35.666667 | C13: 37.333333 | D13: 33
A14: 12 | B14: 35.333333 | C14: 36.666667 | D14: 36.833333
... A54: 52 | B54: 34.75 | C54: 33.6 | D54: 34.25

Sheet Summary Min & Max Def 
B1: Avg Weekly Max Temperature
A2: Week Number | B2: 2023 | C2: 2024 | D2: 2025
A3: 1 | B3: 1.2 | C3: 11.166667 | D3: 7.1666667
A4: 2 | B4: 2 | C4: 10.166667 | D4: 5.5
A5: 3 | B5: 2.6666667 | C5: 13.6 | D5: 5.75
A6: 4 | B6: 2 | C6: 12.6 | D6: 5.3333333
A7: 5 | B7: 5.6 | C7: 13.333333 | D7: 6.5
A8: 6 | B8: 8.5 | C8: 13.333333 | D8: 12.4
A9: 7 | B9: 16.5 | C9: 14.166667 | D9: 11.666667
A10: 8 | B10: 14.4 | C10: 13.8 | D10: 14.166667
A11: 9 | B11: 5.2 | C11: 14 | D11: 11.5
A12: 10 | B12: 12.8 | C12: 15.833333 | D12: 13.5
A13: 11 | B13: 14 | C13: 10.166667 | D13: 6.6666667
A14: 12 | B14: 13.666667 | C14: 13.333333 | D14: 11.333333
... A54: 52 | B54: 14 | C54: 8.8 | D54: 13.25

Sheet RAINFALL (4)
A2: YEAR | B2: WEEK | C2: MONDAY | D2: TUESDAY | E2: WEDNESDAY | F2: THURSDAY | G2: FRIDAY | H2: SATURDAY | I2: Weekly Rain Fall
A3: 2025 | B3: 1 | D3: 20 | E3: 1 | F3: 33 | G3: 0 | H3: 0 | I3: 54
B4: 2 | C4: 0 | D4: 0 | E4: 0 | F4: 0 | G4: 0 | H4: 0 | I4: 0
B5: 3 | C5: 0 | D5: 0 | E5: 54 | F5: 0 | G5: 20 | H5: 0 | I5: 74
B6: 4 | C6: 49 | D6: 1 | E6: 2.5 | F6: 0 | G6: 0 | H6: 38 | I6: 90.5
B7: 5 | C7: 0 | D7: 0 | E7: 0 | F7: 18 | G7: 0 | H7: 9 | I7: 27
B8: 6 | C8: 0 | D8: 0 | E8: 0 | F8: 0 | G8: 0 | H8: 0 | I8: 0
B9: 7 | C9: 0 | D9: 0 | E9: 0 | F9: 0 | G9: 0 | H9: 0 | I9: 0
B10: 8 | C10: 0 | D10: 0 | E10: 0 | F10: 0 | G10: 0 | H10: 0 | I10: 0
B11: 9 | C11: 0 | D11: 0 | E11: 0 | F11: 0 | G11: 0 | H11: 0 | I11: 0
B12: 10 | C12: 57 | D12: 0 | E12: 0 | F12: 0 | G12: 0 | H12: 15 | I12: 72
B13: 11 | C13: 0 | D13: 0 | E13: 0 | F13: 0 | G13: 0 | H13: 0 | I13: 0
B14: 12 | C14: 2.5 | D14: 0 | E14: 0 | F14: 34 | G14: 0 | H14: 0 | I14: 36.5
B15: 13 | C15: 6 | D15: 0 | E15: 0 | F15: 21.5 | G15: 0 | H15: 0 | I15: 27.5
... B52: 50 | C52: 12 | D52: 0 | E52: 0 | F52: 0 | G52: 0 | H52: 3 | I52: 15
B53: 51 | C53: 0 | D53: 0 | E53: 0 | F53: 20 | I53: 20
B54: 52 | I54: 0
C55: 9 | D55: 8 | E55: 4 | F55: 6 | G55: 4 | H55: 4

Sheet RAINFALL (5)
A2: YEAR | B2: WEEK | C2: MONDAY | D2: TUESDAY | E2: WEDNESDAY | F2: THURSDAY | G2: FRIDAY | H2: SATURDAY | I2: Weekly Rain Fall
A3: 2025 | B3: 1 | D3: 20 | E3: 1 | F3: 33 | G3: 0 | H3: 0 | I3: 54
B4: 2 | C4: 0 | D4: 0 | E4: 0 | F4: 0 | G4: 0 | H4: 0 | I4: 0
B5: 3 | C5: 0 | D5: 0 | E5: 54 | F5: 0 | G5: 20 | H5: 0 | I5: 74
B6: 4 | C6: 49 | D6: 1 | E6: 2.5 | F6: 0 | G6: 0 | H6: 38 | I6: 90.5
B7: 5 | C7: 0 | D7: 0 | E7: 0 | F7: 18 | G7: 0 | H7: 9 | I7: 27
B8: 6 | C8: 0 | D8: 0 | E8: 0 | F8: 0 | G8: 0 | H8: 0 | I8: 0
B9: 7 | C9: 0 | D9: 0 | E9: 0 | F9: 0 | G9: 0 | H9: 0 | I9: 0
B10: 8 | C10: 0 | D10: 0 | E10: 0 | F10: 0 | G10: 0 | H10: 0 | I10: 0
B11: 9 | C11: 0 | D11: 0 | E11: 0 | F11: 0 | G11: 0 | H11: 0 | I11: 0
B12: 10 | C12: 57 | D12: 0 | E12: 0 | F12: 0 | G12: 0 | H12: 15 | I12: 72
B13: 11 | C13: 0 | D13: 0 | E13: 0 | F13: 0 | G13: 0 | H13: 0 | I13: 0
B14: 12 | C14: 2.5 | D14: 0 | E14: 0 | F14: 34 | G14: 0 | H14: 0 | I14: 36.5
B15: 13 | C15: 6 | D15: 0 | E15: 0 | F15: 21.5 | G15: 0 | H15: 0 | I15: 27.5
... B52: 50 | C52: 12 | D52: 0 | E52: 0 | F52: 0 | G52: 0 | H52: 3 | I52: 15
B53: 51 | C53: 0 | D53: 0 | E53: 0 | F53: 20 | I53: 20
B54: 52 | I54: 0
C55: 9 | D55: 8 | E55: 4 | F55: 6 | G55: 4 | H55: 4
